<robot name = "robot">
    <link name="Torso">
        <inertial>
            <origin xyz="0 -6 1.0527363924731739" rpy="0 0 0"/>
            <mass value="1" />
            <inertia ixx="100" ixy="0" ixz="0" iyy="100" iyz="0" izz="100" />
        </inertial>
        <visual>
            <origin xyz="0 -6 1.0527363924731739" rpy="0 0 0"/>
            <geometry>
                <box size="1 1 1" />
            </geometry>
            <material name="Cyan">
                <color rgba="0 1.0 1.0 1.0"/>
            </material>
        </visual>
        <collision>
            <origin xyz="0 -6 1.0527363924731739" rpy="0 0 0"/>
            <geometry>
                <box size="1 1 1" />
            </geometry>
        </collision>
    </link>
    <joint name="Torso_FrontLeg" type="revolute">
       <parent link="Torso"/>
       <child  link="FrontLeg"/>
       <origin rpy="0 0 0" xyz="0 -5.5 1.0527363924731739" />
     <axis xyz="1 0 1"/>
       <limit effort="0.0" lower="-3.14159" upper="3.14159" velocity="0.0"/>
    </joint>
    <joint name="Torso_BackLeg" type="revolute">
       <parent link="Torso"/>
       <child  link="BackLeg"/>
       <origin rpy="0 0 0" xyz="0 -6.5 1.0527363924731739" />
     <axis xyz="1 0 1"/>
       <limit effort="0.0" lower="-3.14159" upper="3.14159" velocity="0.0"/>
    </joint>
    <joint name="Torso_LeftLeg" type="revolute">
       <parent link="Torso"/>
       <child  link="LeftLeg"/>
       <origin rpy="0 0 0" xyz="-0.5 -6 1.0527363924731739" />
     <axis xyz="0 1 1"/>
       <limit effort="0.0" lower="-3.14159" upper="3.14159" velocity="0.0"/>
    </joint>
    <joint name="Torso_RightLeg" type="revolute">
       <parent link="Torso"/>
       <child  link="RightLeg"/>
       <origin rpy="0 0 0" xyz="0.5 -6 1.0527363924731739" />
     <axis xyz="0 1 1"/>
       <limit effort="0.0" lower="-3.14159" upper="3.14159" velocity="0.0"/>
    </joint>
    <joint name="FrontLeg_FrontLowerLeg" type="revolute">
       <parent link="FrontLeg"/>
       <child  link="FrontLowerLeg"/>
       <origin rpy="0 0 0" xyz="0 1.2098031886381553 0" />
     <axis xyz="1 0 1"/>
       <limit effort="0.0" lower="-3.14159" upper="3.14159" velocity="0.0"/>
    </joint>
    <joint name="BackLeg_BackLowerLeg" type="revolute">
       <parent link="BackLeg"/>
       <child  link="BackLowerLeg"/>
       <origin rpy="0 0 0" xyz="0 -1.1512539266934048 0" />
     <axis xyz="1 0 1"/>
       <limit effort="0.0" lower="-3.14159" upper="3.14159" velocity="0.0"/>
    </joint>
    <joint name="LeftLeg_LeftLowerLeg" type="revolute">
       <parent link="LeftLeg"/>
       <child  link="LeftLowerLeg"/>
       <origin rpy="0 0 0" xyz="-1.2054574764759949 0 0" />
     <axis xyz="0 1 1"/>
       <limit effort="0.0" lower="-3.14159" upper="3.14159" velocity="0.0"/>
    </joint>
    <joint name="RightLeg_RightLowerLeg" type="revolute">
       <parent link="RightLeg"/>
       <child  link="RightLowerLeg"/>
       <origin rpy="0 0 0" xyz="1.4276586016315664 0 0" />
     <axis xyz="0 1 1"/>
       <limit effort="0.0" lower="-3.14159" upper="3.14159" velocity="0.0"/>
    </joint>
    <link name="FrontLeg">
        <inertial>
            <origin xyz="0 0.6049015943190776 0" rpy="0 0 0"/>
            <mass value="1" />
            <inertia ixx="100" ixy="0" ixz="0" iyy="100" iyz="0" izz="100" />
        </inertial>
        <visual>
            <origin xyz="0 0.6049015943190776 0" rpy="0 0 0"/>
            <geometry>
                <box size="0.2 1.2098031886381553 0.2" />
            </geometry>
            <material name="Cyan">
                <color rgba="0 1.0 1.0 1.0"/>
            </material>
        </visual>
        <collision>
            <origin xyz="0 0.6049015943190776 0" rpy="0 0 0"/>
            <geometry>
                <box size="0.2 1.2098031886381553 0.2" />
            </geometry>
        </collision>
    </link>
    <link name="BackLeg">
        <inertial>
            <origin xyz="0 -0.5756269633467024 0" rpy="0 0 0"/>
            <mass value="1" />
            <inertia ixx="100" ixy="0" ixz="0" iyy="100" iyz="0" izz="100" />
        </inertial>
        <visual>
            <origin xyz="0 -0.5756269633467024 0" rpy="0 0 0"/>
            <geometry>
                <box size="0.2 1.1512539266934048 0.2" />
            </geometry>
            <material name="Cyan">
                <color rgba="0 1.0 1.0 1.0"/>
            </material>
        </visual>
        <collision>
            <origin xyz="0 -0.5756269633467024 0" rpy="0 0 0"/>
            <geometry>
                <box size="0.2 1.1512539266934048 0.2" />
            </geometry>
        </collision>
    </link>
    <link name="LeftLeg">
        <inertial>
            <origin xyz="-0.6027287382379974 0 0" rpy="0 0 0"/>
            <mass value="1" />
            <inertia ixx="100" ixy="0" ixz="0" iyy="100" iyz="0" izz="100" />
        </inertial>
        <visual>
            <origin xyz="-0.6027287382379974 0 0" rpy="0 0 0"/>
            <geometry>
                <box size="1.2054574764759949 0.2 0.2" />
            </geometry>
            <material name="Cyan">
                <color rgba="0 1.0 1.0 1.0"/>
            </material>
        </visual>
        <collision>
            <origin xyz="-0.6027287382379974 0 0" rpy="0 0 0"/>
            <geometry>
                <box size="1.2054574764759949 0.2 0.2" />
            </geometry>
        </collision>
    </link>
    <link name="RightLeg">
        <inertial>
            <origin xyz="0.7138293008157832 0 0" rpy="0 0 0"/>
            <mass value="1" />
            <inertia ixx="100" ixy="0" ixz="0" iyy="100" iyz="0" izz="100" />
        </inertial>
        <visual>
            <origin xyz="0.7138293008157832 0 0" rpy="0 0 0"/>
            <geometry>
                <box size="1.4276586016315664 0.2 0.2" />
            </geometry>
            <material name="Cyan">
                <color rgba="0 1.0 1.0 1.0"/>
            </material>
        </visual>
        <collision>
            <origin xyz="0.7138293008157832 0 0" rpy="0 0 0"/>
            <geometry>
                <box size="1.4276586016315664 0.2 0.2" />
            </geometry>
        </collision>
    </link>
    <link name="FrontLowerLeg">
        <inertial>
            <origin xyz="0 0 -0.2875465720423995" rpy="0 0 0"/>
            <mass value="1" />
            <inertia ixx="100" ixy="0" ixz="0" iyy="100" iyz="0" izz="100" />
        </inertial>
        <visual>
            <origin xyz="0 0 -0.2875465720423995" rpy="0 0 0"/>
            <geometry>
                <box size="0.2 0.2 0.575093144084799" />
            </geometry>
            <material name="Cyan">
                <color rgba="0 1.0 1.0 1.0"/>
            </material>
        </visual>
        <collision>
            <origin xyz="0 0 -0.2875465720423995" rpy="0 0 0"/>
            <geometry>
                <box size="0.2 0.2 0.575093144084799" />
            </geometry>
        </collision>
    </link>
    <link name="BackLowerLeg">
        <inertial>
            <origin xyz="0 0 -0.5239907616462218" rpy="0 0 0"/>
            <mass value="1" />
            <inertia ixx="100" ixy="0" ixz="0" iyy="100" iyz="0" izz="100" />
        </inertial>
        <visual>
            <origin xyz="0 0 -0.5239907616462218" rpy="0 0 0"/>
            <geometry>
                <box size="0.2 0.2 1.0479815232924437" />
            </geometry>
            <material name="Cyan">
                <color rgba="0 1.0 1.0 1.0"/>
            </material>
        </visual>
        <collision>
            <origin xyz="0 0 -0.5239907616462218" rpy="0 0 0"/>
            <geometry>
                <box size="0.2 0.2 1.0479815232924437" />
            </geometry>
        </collision>
    </link>
    <link name="LeftLowerLeg">
        <inertial>
            <origin xyz="0 0 -0.5263681962365869" rpy="0 0 0"/>
            <mass value="1" />
            <inertia ixx="100" ixy="0" ixz="0" iyy="100" iyz="0" izz="100" />
        </inertial>
        <visual>
            <origin xyz="0 0 -0.5263681962365869" rpy="0 0 0"/>
            <geometry>
                <box size="0.2 0.2 1.0527363924731739" />
            </geometry>
            <material name="Cyan">
                <color rgba="0 1.0 1.0 1.0"/>
            </material>
        </visual>
        <collision>
            <origin xyz="0 0 -0.5263681962365869" rpy="0 0 0"/>
            <geometry>
                <box size="0.2 0.2 1.0527363924731739" />
            </geometry>
        </collision>
    </link>
    <link name="RightLowerLeg">
        <inertial>
            <origin xyz="0 0 -0.3398946943003623" rpy="0 0 0"/>
            <mass value="1" />
            <inertia ixx="100" ixy="0" ixz="0" iyy="100" iyz="0" izz="100" />
        </inertial>
        <visual>
            <origin xyz="0 0 -0.3398946943003623" rpy="0 0 0"/>
            <geometry>
                <box size="0.2 0.2 0.6797893886007246" />
            </geometry>
            <material name="Cyan">
                <color rgba="0 1.0 1.0 1.0"/>
            </material>
        </visual>
        <collision>
            <origin xyz="0 0 -0.3398946943003623" rpy="0 0 0"/>
            <geometry>
                <box size="0.2 0.2 0.6797893886007246" />
            </geometry>
        </collision>
    </link>
</robot>