<robot name = "robot">
    <link name="Torso">
        <inertial>
            <origin xyz="0 14 1.176822173534184" rpy="0 0 0"/>
            <mass value="1" />
            <inertia ixx="100" ixy="0" ixz="0" iyy="100" iyz="0" izz="100" />
        </inertial>
        <visual>
            <origin xyz="0 14 1.176822173534184" rpy="0 0 0"/>
            <geometry>
                <box size="1 1 1" />
            </geometry>
            <material name="Cyan">
                <color rgba="0 1.0 1.0 1.0"/>
            </material>
        </visual>
        <collision>
            <origin xyz="0 14 1.176822173534184" rpy="0 0 0"/>
            <geometry>
                <box size="1 1 1" />
            </geometry>
        </collision>
    </link>
    <joint name="Torso_FrontLeg" type="revolute">
       <parent link="Torso"/>
       <child  link="FrontLeg"/>
       <origin rpy="0 0 0" xyz="0 14.5 1.176822173534184" />
     <axis xyz="1 0 1"/>
       <limit effort="0.0" lower="-3.14159" upper="3.14159" velocity="0.0"/>
    </joint>
    <joint name="Torso_BackLeg" type="revolute">
       <parent link="Torso"/>
       <child  link="BackLeg"/>
       <origin rpy="0 0 0" xyz="0 13.5 1.176822173534184" />
     <axis xyz="1 0 1"/>
       <limit effort="0.0" lower="-3.14159" upper="3.14159" velocity="0.0"/>
    </joint>
    <joint name="Torso_LeftLeg" type="revolute">
       <parent link="Torso"/>
       <child  link="LeftLeg"/>
       <origin rpy="0 0 0" xyz="-0.5 14 1.176822173534184" />
     <axis xyz="0 1 1"/>
       <limit effort="0.0" lower="-3.14159" upper="3.14159" velocity="0.0"/>
    </joint>
    <joint name="Torso_RightLeg" type="revolute">
       <parent link="Torso"/>
       <child  link="RightLeg"/>
       <origin rpy="0 0 0" xyz="0.5 14 1.176822173534184" />
     <axis xyz="0 1 1"/>
       <limit effort="0.0" lower="-3.14159" upper="3.14159" velocity="0.0"/>
    </joint>
    <joint name="FrontLeg_FrontLowerLeg" type="revolute">
       <parent link="FrontLeg"/>
       <child  link="FrontLowerLeg"/>
       <origin rpy="0 0 0" xyz="0 1.4030029047572026 0" />
     <axis xyz="1 0 1"/>
       <limit effort="0.0" lower="-3.14159" upper="3.14159" velocity="0.0"/>
    </joint>
    <joint name="BackLeg_BackLowerLeg" type="revolute">
       <parent link="BackLeg"/>
       <child  link="BackLowerLeg"/>
       <origin rpy="0 0 0" xyz="0 -0.6361426335165566 0" />
     <axis xyz="1 0 1"/>
       <limit effort="0.0" lower="-3.14159" upper="3.14159" velocity="0.0"/>
    </joint>
    <joint name="LeftLeg_LeftLowerLeg" type="revolute">
       <parent link="LeftLeg"/>
       <child  link="LeftLowerLeg"/>
       <origin rpy="0 0 0" xyz="-1.381250989452608 0 0" />
     <axis xyz="0 1 1"/>
       <limit effort="0.0" lower="-3.14159" upper="3.14159" velocity="0.0"/>
    </joint>
    <joint name="RightLeg_RightLowerLeg" type="revolute">
       <parent link="RightLeg"/>
       <child  link="RightLowerLeg"/>
       <origin rpy="0 0 0" xyz="0.7910564175844396 0 0" />
     <axis xyz="0 1 1"/>
       <limit effort="0.0" lower="-3.14159" upper="3.14159" velocity="0.0"/>
    </joint>
    <link name="FrontLeg">
        <inertial>
            <origin xyz="0 0.7015014523786013 0" rpy="0 0 0"/>
            <mass value="1" />
            <inertia ixx="100" ixy="0" ixz="0" iyy="100" iyz="0" izz="100" />
        </inertial>
        <visual>
            <origin xyz="0 0.7015014523786013 0" rpy="0 0 0"/>
            <geometry>
                <box size="0.2 1.4030029047572026 0.2" />
            </geometry>
            <material name="Cyan">
                <color rgba="0 1.0 1.0 1.0"/>
            </material>
        </visual>
        <collision>
            <origin xyz="0 0.7015014523786013 0" rpy="0 0 0"/>
            <geometry>
                <box size="0.2 1.4030029047572026 0.2" />
            </geometry>
        </collision>
    </link>
    <link name="BackLeg">
        <inertial>
            <origin xyz="0 -0.3180713167582783 0" rpy="0 0 0"/>
            <mass value="1" />
            <inertia ixx="100" ixy="0" ixz="0" iyy="100" iyz="0" izz="100" />
        </inertial>
        <visual>
            <origin xyz="0 -0.3180713167582783 0" rpy="0 0 0"/>
            <geometry>
                <box size="0.2 0.6361426335165566 0.2" />
            </geometry>
            <material name="Cyan">
                <color rgba="0 1.0 1.0 1.0"/>
            </material>
        </visual>
        <collision>
            <origin xyz="0 -0.3180713167582783 0" rpy="0 0 0"/>
            <geometry>
                <box size="0.2 0.6361426335165566 0.2" />
            </geometry>
        </collision>
    </link>
    <link name="LeftLeg">
        <inertial>
            <origin xyz="-0.690625494726304 0 0" rpy="0 0 0"/>
            <mass value="1" />
            <inertia ixx="100" ixy="0" ixz="0" iyy="100" iyz="0" izz="100" />
        </inertial>
        <visual>
            <origin xyz="-0.690625494726304 0 0" rpy="0 0 0"/>
            <geometry>
                <box size="1.381250989452608 0.2 0.2" />
            </geometry>
            <material name="Cyan">
                <color rgba="0 1.0 1.0 1.0"/>
            </material>
        </visual>
        <collision>
            <origin xyz="-0.690625494726304 0 0" rpy="0 0 0"/>
            <geometry>
                <box size="1.381250989452608 0.2 0.2" />
            </geometry>
        </collision>
    </link>
    <link name="RightLeg">
        <inertial>
            <origin xyz="0.3955282087922198 0 0" rpy="0 0 0"/>
            <mass value="1" />
            <inertia ixx="100" ixy="0" ixz="0" iyy="100" iyz="0" izz="100" />
        </inertial>
        <visual>
            <origin xyz="0.3955282087922198 0 0" rpy="0 0 0"/>
            <geometry>
                <box size="0.7910564175844396 0.2 0.2" />
            </geometry>
            <material name="Cyan">
                <color rgba="0 1.0 1.0 1.0"/>
            </material>
        </visual>
        <collision>
            <origin xyz="0.3955282087922198 0 0" rpy="0 0 0"/>
            <geometry>
                <box size="0.7910564175844396 0.2 0.2" />
            </geometry>
        </collision>
    </link>
    <link name="FrontLowerLeg">
        <inertial>
            <origin xyz="0 0 -0.3480719885400724" rpy="0 0 0"/>
            <mass value="1" />
            <inertia ixx="100" ixy="0" ixz="0" iyy="100" iyz="0" izz="100" />
        </inertial>
        <visual>
            <origin xyz="0 0 -0.3480719885400724" rpy="0 0 0"/>
            <geometry>
                <box size="0.2 0.2 0.6961439770801447" />
            </geometry>
            <material name="Cyan">
                <color rgba="0 1.0 1.0 1.0"/>
            </material>
        </visual>
        <collision>
            <origin xyz="0 0 -0.3480719885400724" rpy="0 0 0"/>
            <geometry>
                <box size="0.2 0.2 0.6961439770801447" />
            </geometry>
        </collision>
    </link>
    <link name="BackLowerLeg">
        <inertial>
            <origin xyz="0 0 -0.36188702831261865" rpy="0 0 0"/>
            <mass value="1" />
            <inertia ixx="100" ixy="0" ixz="0" iyy="100" iyz="0" izz="100" />
        </inertial>
        <visual>
            <origin xyz="0 0 -0.36188702831261865" rpy="0 0 0"/>
            <geometry>
                <box size="0.2 0.2 0.7237740566252373" />
            </geometry>
            <material name="Cyan">
                <color rgba="0 1.0 1.0 1.0"/>
            </material>
        </visual>
        <collision>
            <origin xyz="0 0 -0.36188702831261865" rpy="0 0 0"/>
            <geometry>
                <box size="0.2 0.2 0.7237740566252373" />
            </geometry>
        </collision>
    </link>
    <link name="LeftLowerLeg">
        <inertial>
            <origin xyz="0 0 -0.588411086767092" rpy="0 0 0"/>
            <mass value="1" />
            <inertia ixx="100" ixy="0" ixz="0" iyy="100" iyz="0" izz="100" />
        </inertial>
        <visual>
            <origin xyz="0 0 -0.588411086767092" rpy="0 0 0"/>
            <geometry>
                <box size="0.2 0.2 1.176822173534184" />
            </geometry>
            <material name="Cyan">
                <color rgba="0 1.0 1.0 1.0"/>
            </material>
        </visual>
        <collision>
            <origin xyz="0 0 -0.588411086767092" rpy="0 0 0"/>
            <geometry>
                <box size="0.2 0.2 1.176822173534184" />
            </geometry>
        </collision>
    </link>
    <link name="RightLowerLeg">
        <inertial>
            <origin xyz="0 0 -0.2511626759113819" rpy="0 0 0"/>
            <mass value="1" />
            <inertia ixx="100" ixy="0" ixz="0" iyy="100" iyz="0" izz="100" />
        </inertial>
        <visual>
            <origin xyz="0 0 -0.2511626759113819" rpy="0 0 0"/>
            <geometry>
                <box size="0.2 0.2 0.5023253518227638" />
            </geometry>
            <material name="Cyan">
                <color rgba="0 1.0 1.0 1.0"/>
            </material>
        </visual>
        <collision>
            <origin xyz="0 0 -0.2511626759113819" rpy="0 0 0"/>
            <geometry>
                <box size="0.2 0.2 0.5023253518227638" />
            </geometry>
        </collision>
    </link>
</robot>