<robot name = "robot">
    <link name="Torso">
        <inertial>
            <origin xyz="0 10 1.4027778973583538" rpy="0 0 0"/>
            <mass value="1" />
            <inertia ixx="100" ixy="0" ixz="0" iyy="100" iyz="0" izz="100" />
        </inertial>
        <visual>
            <origin xyz="0 10 1.4027778973583538" rpy="0 0 0"/>
            <geometry>
                <box size="1 1 1" />
            </geometry>
            <material name="Cyan">
                <color rgba="0 1.0 1.0 1.0"/>
            </material>
        </visual>
        <collision>
            <origin xyz="0 10 1.4027778973583538" rpy="0 0 0"/>
            <geometry>
                <box size="1 1 1" />
            </geometry>
        </collision>
    </link>
    <joint name="Torso_FrontLeg" type="revolute">
       <parent link="Torso"/>
       <child  link="FrontLeg"/>
       <origin rpy="0 0 0" xyz="0 10.5 1.4027778973583538" />
     <axis xyz="1 0 1"/>
       <limit effort="0.0" lower="-3.14159" upper="3.14159" velocity="0.0"/>
    </joint>
    <joint name="Torso_BackLeg" type="revolute">
       <parent link="Torso"/>
       <child  link="BackLeg"/>
       <origin rpy="0 0 0" xyz="0 9.5 1.4027778973583538" />
     <axis xyz="1 0 1"/>
       <limit effort="0.0" lower="-3.14159" upper="3.14159" velocity="0.0"/>
    </joint>
    <joint name="Torso_LeftLeg" type="revolute">
       <parent link="Torso"/>
       <child  link="LeftLeg"/>
       <origin rpy="0 0 0" xyz="-0.5 10 1.4027778973583538" />
     <axis xyz="0 1 1"/>
       <limit effort="0.0" lower="-3.14159" upper="3.14159" velocity="0.0"/>
    </joint>
    <joint name="Torso_RightLeg" type="revolute">
       <parent link="Torso"/>
       <child  link="RightLeg"/>
       <origin rpy="0 0 0" xyz="0.5 10 1.4027778973583538" />
     <axis xyz="0 1 1"/>
       <limit effort="0.0" lower="-3.14159" upper="3.14159" velocity="0.0"/>
    </joint>
    <joint name="FrontLeg_FrontLowerLeg" type="revolute">
       <parent link="FrontLeg"/>
       <child  link="FrontLowerLeg"/>
       <origin rpy="0 0 0" xyz="0 0.6388820588611498 0" />
     <axis xyz="1 0 1"/>
       <limit effort="0.0" lower="-3.14159" upper="3.14159" velocity="0.0"/>
    </joint>
    <joint name="BackLeg_BackLowerLeg" type="revolute">
       <parent link="BackLeg"/>
       <child  link="BackLowerLeg"/>
       <origin rpy="0 0 0" xyz="0 -1.4404612146168008 0" />
     <axis xyz="1 0 1"/>
       <limit effort="0.0" lower="-3.14159" upper="3.14159" velocity="0.0"/>
    </joint>
    <joint name="LeftLeg_LeftLowerLeg" type="revolute">
       <parent link="LeftLeg"/>
       <child  link="LeftLowerLeg"/>
       <origin rpy="0 0 0" xyz="-0.5371985067054709 0 0" />
     <axis xyz="0 1 1"/>
       <limit effort="0.0" lower="-3.14159" upper="3.14159" velocity="0.0"/>
    </joint>
    <joint name="RightLeg_RightLowerLeg" type="revolute">
       <parent link="RightLeg"/>
       <child  link="RightLowerLeg"/>
       <origin rpy="0 0 0" xyz="0.8821612095021335 0 0" />
     <axis xyz="0 1 1"/>
       <limit effort="0.0" lower="-3.14159" upper="3.14159" velocity="0.0"/>
    </joint>
    <link name="FrontLeg">
        <inertial>
            <origin xyz="0 0.3194410294305749 0" rpy="0 0 0"/>
            <mass value="1" />
            <inertia ixx="100" ixy="0" ixz="0" iyy="100" iyz="0" izz="100" />
        </inertial>
        <visual>
            <origin xyz="0 0.3194410294305749 0" rpy="0 0 0"/>
            <geometry>
                <box size="0.2 0.6388820588611498 0.2" />
            </geometry>
            <material name="Cyan">
                <color rgba="0 1.0 1.0 1.0"/>
            </material>
        </visual>
        <collision>
            <origin xyz="0 0.3194410294305749 0" rpy="0 0 0"/>
            <geometry>
                <box size="0.2 0.6388820588611498 0.2" />
            </geometry>
        </collision>
    </link>
    <link name="BackLeg">
        <inertial>
            <origin xyz="0 -0.7202306073084004 0" rpy="0 0 0"/>
            <mass value="1" />
            <inertia ixx="100" ixy="0" ixz="0" iyy="100" iyz="0" izz="100" />
        </inertial>
        <visual>
            <origin xyz="0 -0.7202306073084004 0" rpy="0 0 0"/>
            <geometry>
                <box size="0.2 1.4404612146168008 0.2" />
            </geometry>
            <material name="Cyan">
                <color rgba="0 1.0 1.0 1.0"/>
            </material>
        </visual>
        <collision>
            <origin xyz="0 -0.7202306073084004 0" rpy="0 0 0"/>
            <geometry>
                <box size="0.2 1.4404612146168008 0.2" />
            </geometry>
        </collision>
    </link>
    <link name="LeftLeg">
        <inertial>
            <origin xyz="-0.26859925335273543 0 0" rpy="0 0 0"/>
            <mass value="1" />
            <inertia ixx="100" ixy="0" ixz="0" iyy="100" iyz="0" izz="100" />
        </inertial>
        <visual>
            <origin xyz="-0.26859925335273543 0 0" rpy="0 0 0"/>
            <geometry>
                <box size="0.5371985067054709 0.2 0.2" />
            </geometry>
            <material name="Cyan">
                <color rgba="0 1.0 1.0 1.0"/>
            </material>
        </visual>
        <collision>
            <origin xyz="-0.26859925335273543 0 0" rpy="0 0 0"/>
            <geometry>
                <box size="0.5371985067054709 0.2 0.2" />
            </geometry>
        </collision>
    </link>
    <link name="RightLeg">
        <inertial>
            <origin xyz="0.44108060475106675 0 0" rpy="0 0 0"/>
            <mass value="1" />
            <inertia ixx="100" ixy="0" ixz="0" iyy="100" iyz="0" izz="100" />
        </inertial>
        <visual>
            <origin xyz="0.44108060475106675 0 0" rpy="0 0 0"/>
            <geometry>
                <box size="0.8821612095021335 0.2 0.2" />
            </geometry>
            <material name="Cyan">
                <color rgba="0 1.0 1.0 1.0"/>
            </material>
        </visual>
        <collision>
            <origin xyz="0.44108060475106675 0 0" rpy="0 0 0"/>
            <geometry>
                <box size="0.8821612095021335 0.2 0.2" />
            </geometry>
        </collision>
    </link>
    <link name="FrontLowerLeg">
        <inertial>
            <origin xyz="0 0 -0.31738862263676093" rpy="0 0 0"/>
            <mass value="1" />
            <inertia ixx="100" ixy="0" ixz="0" iyy="100" iyz="0" izz="100" />
        </inertial>
        <visual>
            <origin xyz="0 0 -0.31738862263676093" rpy="0 0 0"/>
            <geometry>
                <box size="0.2 0.2 0.6347772452735219" />
            </geometry>
            <material name="Cyan">
                <color rgba="0 1.0 1.0 1.0"/>
            </material>
        </visual>
        <collision>
            <origin xyz="0 0 -0.31738862263676093" rpy="0 0 0"/>
            <geometry>
                <box size="0.2 0.2 0.6347772452735219" />
            </geometry>
        </collision>
    </link>
    <link name="BackLowerLeg">
        <inertial>
            <origin xyz="0 0 -0.5793123929411295" rpy="0 0 0"/>
            <mass value="1" />
            <inertia ixx="100" ixy="0" ixz="0" iyy="100" iyz="0" izz="100" />
        </inertial>
        <visual>
            <origin xyz="0 0 -0.5793123929411295" rpy="0 0 0"/>
            <geometry>
                <box size="0.2 0.2 1.158624785882259" />
            </geometry>
            <material name="Cyan">
                <color rgba="0 1.0 1.0 1.0"/>
            </material>
        </visual>
        <collision>
            <origin xyz="0 0 -0.5793123929411295" rpy="0 0 0"/>
            <geometry>
                <box size="0.2 0.2 1.158624785882259" />
            </geometry>
        </collision>
    </link>
    <link name="LeftLowerLeg">
        <inertial>
            <origin xyz="0 0 -0.6495610297795601" rpy="0 0 0"/>
            <mass value="1" />
            <inertia ixx="100" ixy="0" ixz="0" iyy="100" iyz="0" izz="100" />
        </inertial>
        <visual>
            <origin xyz="0 0 -0.6495610297795601" rpy="0 0 0"/>
            <geometry>
                <box size="0.2 0.2 1.2991220595591202" />
            </geometry>
            <material name="Cyan">
                <color rgba="0 1.0 1.0 1.0"/>
            </material>
        </visual>
        <collision>
            <origin xyz="0 0 -0.6495610297795601" rpy="0 0 0"/>
            <geometry>
                <box size="0.2 0.2 1.2991220595591202" />
            </geometry>
        </collision>
    </link>
    <link name="RightLowerLeg">
        <inertial>
            <origin xyz="0 0 -0.7013889486791769" rpy="0 0 0"/>
            <mass value="1" />
            <inertia ixx="100" ixy="0" ixz="0" iyy="100" iyz="0" izz="100" />
        </inertial>
        <visual>
            <origin xyz="0 0 -0.7013889486791769" rpy="0 0 0"/>
            <geometry>
                <box size="0.2 0.2 1.4027778973583538" />
            </geometry>
            <material name="Cyan">
                <color rgba="0 1.0 1.0 1.0"/>
            </material>
        </visual>
        <collision>
            <origin xyz="0 0 -0.7013889486791769" rpy="0 0 0"/>
            <geometry>
                <box size="0.2 0.2 1.4027778973583538" />
            </geometry>
        </collision>
    </link>
</robot>