<robot name = "robot">
    <link name="Torso">
        <inertial>
            <origin xyz="0 10 2.489092735911429" rpy="0 0 0"/>
            <mass value="1" />
            <inertia ixx="100" ixy="0" ixz="0" iyy="100" iyz="0" izz="100" />
        </inertial>
        <visual>
            <origin xyz="0 10 2.489092735911429" rpy="0 0 0"/>
            <geometry>
                <box size="1 1 1" />
            </geometry>
            <material name="Cyan">
                <color rgba="0 1.0 1.0 1.0"/>
            </material>
        </visual>
        <collision>
            <origin xyz="0 10 2.489092735911429" rpy="0 0 0"/>
            <geometry>
                <box size="1 1 1" />
            </geometry>
        </collision>
    </link>
    <joint name="Torso_BackLeg" type="revolute">
       <parent link="Torso"/>
       <child  link="BackLeg"/>
       <origin rpy="0 0 0" xyz="0 9.5 2.489092735911429" />
     <axis xyz="1 0 0"/>
       <limit effort="0.0" lower="-3.14159" upper="3.14159" velocity="0.0"/>
    </joint>
    <link name="BackLeg">
        <inertial>
            <origin xyz="0 -0.2825300001510836 0" rpy="0 0 0"/>
            <mass value="1" />
            <inertia ixx="100" ixy="0" ixz="0" iyy="100" iyz="0" izz="100" />
        </inertial>
        <visual>
            <origin xyz="0 -0.2825300001510836 0" rpy="0 0 0"/>
            <geometry>
                <box size="0.2 0.5650600003021672 0.2" />
            </geometry>
            <material name="Cyan">
                <color rgba="0 1.0 1.0 1.0"/>
            </material>
        </visual>
        <collision>
            <origin xyz="0 -0.2825300001510836 0" rpy="0 0 0"/>
            <geometry>
                <box size="0.2 0.5650600003021672 0.2" />
            </geometry>
        </collision>
    </link>
    <joint name="Torso_FrontLeg" type="revolute">
       <parent link="Torso"/>
       <child  link="FrontLeg"/>
       <origin rpy="0 0 0" xyz="0 10.5 2.489092735911429" />
     <axis xyz="1 0 0"/>
       <limit effort="0.0" lower="-3.14159" upper="3.14159" velocity="0.0"/>
    </joint>
    <link name="FrontLeg">
        <inertial>
            <origin xyz="0 0.2516606630206772 0" rpy="0 0 0"/>
            <mass value="1" />
            <inertia ixx="100" ixy="0" ixz="0" iyy="100" iyz="0" izz="100" />
        </inertial>
        <visual>
            <origin xyz="0 0.2516606630206772 0" rpy="0 0 0"/>
            <geometry>
                <box size="0.2 0.5033213260413544 0.2" />
            </geometry>
            <material name="Cyan">
                <color rgba="0 1.0 1.0 1.0"/>
            </material>
        </visual>
        <collision>
            <origin xyz="0 0.2516606630206772 0" rpy="0 0 0"/>
            <geometry>
                <box size="0.2 0.5033213260413544 0.2" />
            </geometry>
        </collision>
    </link>
    <joint name="Torso_LeftLeg" type="revolute">
       <parent link="Torso"/>
       <child  link="LeftLeg"/>
       <origin rpy="0 0 0" xyz="-0.5 10 2.489092735911429" />
     <axis xyz="0 1 0"/>
       <limit effort="0.0" lower="-3.14159" upper="3.14159" velocity="0.0"/>
    </joint>
    <link name="LeftLeg">
        <inertial>
            <origin xyz="-0.3748416810685036 0 0" rpy="0 0 0"/>
            <mass value="1" />
            <inertia ixx="100" ixy="0" ixz="0" iyy="100" iyz="0" izz="100" />
        </inertial>
        <visual>
            <origin xyz="-0.3748416810685036 0 0" rpy="0 0 0"/>
            <geometry>
                <box size="0.7496833621370071 0.2 0.2" />
            </geometry>
            <material name="Cyan">
                <color rgba="0 1.0 1.0 1.0"/>
            </material>
        </visual>
        <collision>
            <origin xyz="-0.3748416810685036 0 0" rpy="0 0 0"/>
            <geometry>
                <box size="0.7496833621370071 0.2 0.2" />
            </geometry>
        </collision>
    </link>
    <joint name="Torso_RightLeg" type="revolute">
       <parent link="Torso"/>
       <child  link="RightLeg"/>
       <origin rpy="0 0 0" xyz="0.5 10 2.489092735911429" />
     <axis xyz="0 1 0"/>
       <limit effort="0.0" lower="-3.14159" upper="3.14159" velocity="0.0"/>
    </joint>
    <link name="RightLeg">
        <inertial>
            <origin xyz="0.7445463679557146 0 0" rpy="0 0 0"/>
            <mass value="1" />
            <inertia ixx="100" ixy="0" ixz="0" iyy="100" iyz="0" izz="100" />
        </inertial>
        <visual>
            <origin xyz="0.7445463679557146 0 0" rpy="0 0 0"/>
            <geometry>
                <box size="1.4890927359114292 0.2 0.2" />
            </geometry>
            <material name="Cyan">
                <color rgba="0 1.0 1.0 1.0"/>
            </material>
        </visual>
        <collision>
            <origin xyz="0.7445463679557146 0 0" rpy="0 0 0"/>
            <geometry>
                <box size="1.4890927359114292 0.2 0.2" />
            </geometry>
        </collision>
    </link>
    <joint name="BackLeg_BackLowerLeg" type="revolute">
       <parent link="BackLeg"/>
       <child  link="BackLowerLeg"/>
       <origin rpy="0 0 0" xyz="0 -0.5650600003021672 0" />
     <axis xyz="1 0 0"/>
       <limit effort="0.0" lower="-3.14159" upper="3.14159" velocity="0.0"/>
    </joint>
    <link name="BackLowerLeg">
        <inertial>
            <origin xyz="0 0 -0.28142214501864793" rpy="0 0 0"/>
            <mass value="1" />
            <inertia ixx="100" ixy="0" ixz="0" iyy="100" iyz="0" izz="100" />
        </inertial>
        <visual>
            <origin xyz="0 0 -0.28142214501864793" rpy="0 0 0"/>
            <geometry>
                <box size="0.2 0.2 0.5628442900372959" />
            </geometry>
            <material name="Cyan">
                <color rgba="0 1.0 1.0 1.0"/>
            </material>
        </visual>
        <collision>
            <origin xyz="0 0 -0.28142214501864793" rpy="0 0 0"/>
            <geometry>
                <box size="0.2 0.2 0.5628442900372959" />
            </geometry>
        </collision>
    </link>
    <joint name="FrontLeg_FrontLowerLeg" type="revolute">
       <parent link="FrontLeg"/>
       <child  link="FrontLowerLeg"/>
       <origin rpy="0 0 0" xyz="0 0.5033213260413544 0" />
     <axis xyz="1 0 0"/>
       <limit effort="0.0" lower="-3.14159" upper="3.14159" velocity="0.0"/>
    </joint>
    <link name="FrontLowerLeg">
        <inertial>
            <origin xyz="0 0 -0.7308122794477436" rpy="0 0 0"/>
            <mass value="1" />
            <inertia ixx="100" ixy="0" ixz="0" iyy="100" iyz="0" izz="100" />
        </inertial>
        <visual>
            <origin xyz="0 0 -0.7308122794477436" rpy="0 0 0"/>
            <geometry>
                <box size="0.2 0.2 1.4616245588954873" />
            </geometry>
            <material name="Cyan">
                <color rgba="0 1.0 1.0 1.0"/>
            </material>
        </visual>
        <collision>
            <origin xyz="0 0 -0.7308122794477436" rpy="0 0 0"/>
            <geometry>
                <box size="0.2 0.2 1.4616245588954873" />
            </geometry>
        </collision>
    </link>
    <joint name="LeftLeg_LeftLowerLeg" type="revolute">
       <parent link="LeftLeg"/>
       <child  link="LeftLowerLeg"/>
       <origin rpy="0 0 0" xyz="-0.7496833621370071 0 0" />
     <axis xyz="0 1 0"/>
       <limit effort="0.0" lower="-3.14159" upper="3.14159" velocity="0.0"/>
    </joint>
    <link name="LeftLowerLeg">
        <inertial>
            <origin xyz="0 0 -0.5994125644896034" rpy="0 0 0"/>
            <mass value="1" />
            <inertia ixx="100" ixy="0" ixz="0" iyy="100" iyz="0" izz="100" />
        </inertial>
        <visual>
            <origin xyz="0 0 -0.5994125644896034" rpy="0 0 0"/>
            <geometry>
                <box size="0.2 0.2 1.198825128979207" />
            </geometry>
            <material name="Cyan">
                <color rgba="0 1.0 1.0 1.0"/>
            </material>
        </visual>
        <collision>
            <origin xyz="0 0 -0.5994125644896034" rpy="0 0 0"/>
            <geometry>
                <box size="0.2 0.2 1.198825128979207" />
            </geometry>
        </collision>
    </link>
    <joint name="RightLeg_RightLowerLeg" type="revolute">
       <parent link="RightLeg"/>
       <child  link="RightLowerLeg"/>
       <origin rpy="0 0 0" xyz="1.4890927359114292 0 0" />
     <axis xyz="0 1 0"/>
       <limit effort="0.0" lower="-3.14159" upper="3.14159" velocity="0.0"/>
    </joint>
    <link name="RightLowerLeg">
        <inertial>
            <origin xyz="0 0 -0.3891321314362534" rpy="0 0 0"/>
            <mass value="1" />
            <inertia ixx="100" ixy="0" ixz="0" iyy="100" iyz="0" izz="100" />
        </inertial>
        <visual>
            <origin xyz="0 0 -0.3891321314362534" rpy="0 0 0"/>
            <geometry>
                <box size="0.2 0.2 0.7782642628725068" />
            </geometry>
            <material name="Cyan">
                <color rgba="0 1.0 1.0 1.0"/>
            </material>
        </visual>
        <collision>
            <origin xyz="0 0 -0.3891321314362534" rpy="0 0 0"/>
            <geometry>
                <box size="0.2 0.2 0.7782642628725068" />
            </geometry>
        </collision>
    </link>
</robot>