<robot name = "robot">
    <link name="Torso">
        <inertial>
            <origin xyz="0 0 1.482141539777464" rpy="0 0 0"/>
            <mass value="1" />
            <inertia ixx="100" ixy="0" ixz="0" iyy="100" iyz="0" izz="100" />
        </inertial>
        <visual>
            <origin xyz="0 0 1.482141539777464" rpy="0 0 0"/>
            <geometry>
                <box size="1 1 1" />
            </geometry>
            <material name="Cyan">
                <color rgba="0 1.0 1.0 1.0"/>
            </material>
        </visual>
        <collision>
            <origin xyz="0 0 1.482141539777464" rpy="0 0 0"/>
            <geometry>
                <box size="1 1 1" />
            </geometry>
        </collision>
    </link>
    <joint name="Torso_FrontLeg" type="revolute">
       <parent link="Torso"/>
       <child  link="FrontLeg"/>
       <origin rpy="0 0 0" xyz="0 0.5 1.482141539777464" />
     <axis xyz="1 0 1"/>
       <limit effort="0.0" lower="-3.14159" upper="3.14159" velocity="0.0"/>
    </joint>
    <joint name="Torso_BackLeg" type="revolute">
       <parent link="Torso"/>
       <child  link="BackLeg"/>
       <origin rpy="0 0 0" xyz="0 -0.5 1.482141539777464" />
     <axis xyz="1 0 1"/>
       <limit effort="0.0" lower="-3.14159" upper="3.14159" velocity="0.0"/>
    </joint>
    <joint name="Torso_LeftLeg" type="revolute">
       <parent link="Torso"/>
       <child  link="LeftLeg"/>
       <origin rpy="0 0 0" xyz="-0.5 0 1.482141539777464" />
     <axis xyz="0 1 1"/>
       <limit effort="0.0" lower="-3.14159" upper="3.14159" velocity="0.0"/>
    </joint>
    <joint name="Torso_RightLeg" type="revolute">
       <parent link="Torso"/>
       <child  link="RightLeg"/>
       <origin rpy="0 0 0" xyz="0.5 0 1.482141539777464" />
     <axis xyz="0 1 1"/>
       <limit effort="0.0" lower="-3.14159" upper="3.14159" velocity="0.0"/>
    </joint>
    <joint name="FrontLeg_FrontLowerLeg" type="revolute">
       <parent link="FrontLeg"/>
       <child  link="FrontLowerLeg"/>
       <origin rpy="0 0 0" xyz="0 0.8804618626168021 0" />
     <axis xyz="1 0 1"/>
       <limit effort="0.0" lower="-3.14159" upper="3.14159" velocity="0.0"/>
    </joint>
    <joint name="BackLeg_BackLowerLeg" type="revolute">
       <parent link="BackLeg"/>
       <child  link="BackLowerLeg"/>
       <origin rpy="0 0 0" xyz="0 -1.2469671833629827 0" />
     <axis xyz="1 0 1"/>
       <limit effort="0.0" lower="-3.14159" upper="3.14159" velocity="0.0"/>
    </joint>
    <joint name="LeftLeg_LeftLowerLeg" type="revolute">
       <parent link="LeftLeg"/>
       <child  link="LeftLowerLeg"/>
       <origin rpy="0 0 0" xyz="-1.2012259435605008 0 0" />
     <axis xyz="0 1 1"/>
       <limit effort="0.0" lower="-3.14159" upper="3.14159" velocity="0.0"/>
    </joint>
    <joint name="RightLeg_RightLowerLeg" type="revolute">
       <parent link="RightLeg"/>
       <child  link="RightLowerLeg"/>
       <origin rpy="0 0 0" xyz="0.9742737873364432 0 0" />
     <axis xyz="0 1 1"/>
       <limit effort="0.0" lower="-3.14159" upper="3.14159" velocity="0.0"/>
    </joint>
    <link name="FrontLeg">
        <inertial>
            <origin xyz="0 0.4402309313084011 0" rpy="0 0 0"/>
            <mass value="1" />
            <inertia ixx="100" ixy="0" ixz="0" iyy="100" iyz="0" izz="100" />
        </inertial>
        <visual>
            <origin xyz="0 0.4402309313084011 0" rpy="0 0 0"/>
            <geometry>
                <box size="0.2 0.8804618626168021 0.2" />
            </geometry>
            <material name="Cyan">
                <color rgba="0 1.0 1.0 1.0"/>
            </material>
        </visual>
        <collision>
            <origin xyz="0 0.4402309313084011 0" rpy="0 0 0"/>
            <geometry>
                <box size="0.2 0.8804618626168021 0.2" />
            </geometry>
        </collision>
    </link>
    <link name="BackLeg">
        <inertial>
            <origin xyz="0 -0.6234835916814914 0" rpy="0 0 0"/>
            <mass value="1" />
            <inertia ixx="100" ixy="0" ixz="0" iyy="100" iyz="0" izz="100" />
        </inertial>
        <visual>
            <origin xyz="0 -0.6234835916814914 0" rpy="0 0 0"/>
            <geometry>
                <box size="0.2 1.2469671833629827 0.2" />
            </geometry>
            <material name="Cyan">
                <color rgba="0 1.0 1.0 1.0"/>
            </material>
        </visual>
        <collision>
            <origin xyz="0 -0.6234835916814914 0" rpy="0 0 0"/>
            <geometry>
                <box size="0.2 1.2469671833629827 0.2" />
            </geometry>
        </collision>
    </link>
    <link name="LeftLeg">
        <inertial>
            <origin xyz="-0.6006129717802504 0 0" rpy="0 0 0"/>
            <mass value="1" />
            <inertia ixx="100" ixy="0" ixz="0" iyy="100" iyz="0" izz="100" />
        </inertial>
        <visual>
            <origin xyz="-0.6006129717802504 0 0" rpy="0 0 0"/>
            <geometry>
                <box size="1.2012259435605008 0.2 0.2" />
            </geometry>
            <material name="Cyan">
                <color rgba="0 1.0 1.0 1.0"/>
            </material>
        </visual>
        <collision>
            <origin xyz="-0.6006129717802504 0 0" rpy="0 0 0"/>
            <geometry>
                <box size="1.2012259435605008 0.2 0.2" />
            </geometry>
        </collision>
    </link>
    <link name="RightLeg">
        <inertial>
            <origin xyz="0.4871368936682216 0 0" rpy="0 0 0"/>
            <mass value="1" />
            <inertia ixx="100" ixy="0" ixz="0" iyy="100" iyz="0" izz="100" />
        </inertial>
        <visual>
            <origin xyz="0.4871368936682216 0 0" rpy="0 0 0"/>
            <geometry>
                <box size="0.9742737873364432 0.2 0.2" />
            </geometry>
            <material name="Cyan">
                <color rgba="0 1.0 1.0 1.0"/>
            </material>
        </visual>
        <collision>
            <origin xyz="0.4871368936682216 0 0" rpy="0 0 0"/>
            <geometry>
                <box size="0.9742737873364432 0.2 0.2" />
            </geometry>
        </collision>
    </link>
    <link name="FrontLowerLeg">
        <inertial>
            <origin xyz="0 0 -0.4695648324144154" rpy="0 0 0"/>
            <mass value="1" />
            <inertia ixx="100" ixy="0" ixz="0" iyy="100" iyz="0" izz="100" />
        </inertial>
        <visual>
            <origin xyz="0 0 -0.4695648324144154" rpy="0 0 0"/>
            <geometry>
                <box size="0.2 0.2 0.9391296648288308" />
            </geometry>
            <material name="Cyan">
                <color rgba="0 1.0 1.0 1.0"/>
            </material>
        </visual>
        <collision>
            <origin xyz="0 0 -0.4695648324144154" rpy="0 0 0"/>
            <geometry>
                <box size="0.2 0.2 0.9391296648288308" />
            </geometry>
        </collision>
    </link>
    <link name="BackLowerLeg">
        <inertial>
            <origin xyz="0 0 -0.7183105245110198" rpy="0 0 0"/>
            <mass value="1" />
            <inertia ixx="100" ixy="0" ixz="0" iyy="100" iyz="0" izz="100" />
        </inertial>
        <visual>
            <origin xyz="0 0 -0.7183105245110198" rpy="0 0 0"/>
            <geometry>
                <box size="0.2 0.2 1.4366210490220397" />
            </geometry>
            <material name="Cyan">
                <color rgba="0 1.0 1.0 1.0"/>
            </material>
        </visual>
        <collision>
            <origin xyz="0 0 -0.7183105245110198" rpy="0 0 0"/>
            <geometry>
                <box size="0.2 0.2 1.4366210490220397" />
            </geometry>
        </collision>
    </link>
    <link name="LeftLowerLeg">
        <inertial>
            <origin xyz="0 0 -0.741070769888732" rpy="0 0 0"/>
            <mass value="1" />
            <inertia ixx="100" ixy="0" ixz="0" iyy="100" iyz="0" izz="100" />
        </inertial>
        <visual>
            <origin xyz="0 0 -0.741070769888732" rpy="0 0 0"/>
            <geometry>
                <box size="0.2 0.2 1.482141539777464" />
            </geometry>
            <material name="Cyan">
                <color rgba="0 1.0 1.0 1.0"/>
            </material>
        </visual>
        <collision>
            <origin xyz="0 0 -0.741070769888732" rpy="0 0 0"/>
            <geometry>
                <box size="0.2 0.2 1.482141539777464" />
            </geometry>
        </collision>
    </link>
    <link name="RightLowerLeg">
        <inertial>
            <origin xyz="0 0 -0.5295224473684221" rpy="0 0 0"/>
            <mass value="1" />
            <inertia ixx="100" ixy="0" ixz="0" iyy="100" iyz="0" izz="100" />
        </inertial>
        <visual>
            <origin xyz="0 0 -0.5295224473684221" rpy="0 0 0"/>
            <geometry>
                <box size="0.2 0.2 1.0590448947368443" />
            </geometry>
            <material name="Cyan">
                <color rgba="0 1.0 1.0 1.0"/>
            </material>
        </visual>
        <collision>
            <origin xyz="0 0 -0.5295224473684221" rpy="0 0 0"/>
            <geometry>
                <box size="0.2 0.2 1.0590448947368443" />
            </geometry>
        </collision>
    </link>
</robot>