<robot name = "robot">
    <link name="Torso">
        <inertial>
            <origin xyz="0 0 1.3112323215134365" rpy="0 0 0"/>
            <mass value="1" />
            <inertia ixx="100" ixy="0" ixz="0" iyy="100" iyz="0" izz="100" />
        </inertial>
        <visual>
            <origin xyz="0 0 1.3112323215134365" rpy="0 0 0"/>
            <geometry>
                <box size="1 1 1" />
            </geometry>
            <material name="Cyan">
                <color rgba="0 1.0 1.0 1.0"/>
            </material>
        </visual>
        <collision>
            <origin xyz="0 0 1.3112323215134365" rpy="0 0 0"/>
            <geometry>
                <box size="1 1 1" />
            </geometry>
        </collision>
    </link>
    <joint name="Torso_FrontLeg" type="revolute">
       <parent link="Torso"/>
       <child  link="FrontLeg"/>
       <origin rpy="0 0 0" xyz="0 0.5 1.3112323215134365" />
     <axis xyz="1 0 1"/>
       <limit effort="0.0" lower="-3.14159" upper="3.14159" velocity="0.0"/>
    </joint>
    <joint name="Torso_BackLeg" type="revolute">
       <parent link="Torso"/>
       <child  link="BackLeg"/>
       <origin rpy="0 0 0" xyz="0 -0.5 1.3112323215134365" />
     <axis xyz="1 0 1"/>
       <limit effort="0.0" lower="-3.14159" upper="3.14159" velocity="0.0"/>
    </joint>
    <joint name="Torso_LeftLeg" type="revolute">
       <parent link="Torso"/>
       <child  link="LeftLeg"/>
       <origin rpy="0 0 0" xyz="-0.5 0 1.3112323215134365" />
     <axis xyz="0 1 1"/>
       <limit effort="0.0" lower="-3.14159" upper="3.14159" velocity="0.0"/>
    </joint>
    <joint name="Torso_RightLeg" type="revolute">
       <parent link="Torso"/>
       <child  link="RightLeg"/>
       <origin rpy="0 0 0" xyz="0.5 0 1.3112323215134365" />
     <axis xyz="0 1 1"/>
       <limit effort="0.0" lower="-3.14159" upper="3.14159" velocity="0.0"/>
    </joint>
    <joint name="FrontLeg_FrontLowerLeg" type="revolute">
       <parent link="FrontLeg"/>
       <child  link="FrontLowerLeg"/>
       <origin rpy="0 0 0" xyz="0 0.8404039574687403 0" />
     <axis xyz="1 0 1"/>
       <limit effort="0.0" lower="-3.14159" upper="3.14159" velocity="0.0"/>
    </joint>
    <joint name="BackLeg_BackLowerLeg" type="revolute">
       <parent link="BackLeg"/>
       <child  link="BackLowerLeg"/>
       <origin rpy="0 0 0" xyz="0 -0.8299960582101786 0" />
     <axis xyz="1 0 1"/>
       <limit effort="0.0" lower="-3.14159" upper="3.14159" velocity="0.0"/>
    </joint>
    <joint name="LeftLeg_LeftLowerLeg" type="revolute">
       <parent link="LeftLeg"/>
       <child  link="LeftLowerLeg"/>
       <origin rpy="0 0 0" xyz="-1.2142434227433274 0 0" />
     <axis xyz="0 1 1"/>
       <limit effort="0.0" lower="-3.14159" upper="3.14159" velocity="0.0"/>
    </joint>
    <joint name="RightLeg_RightLowerLeg" type="revolute">
       <parent link="RightLeg"/>
       <child  link="RightLowerLeg"/>
       <origin rpy="0 0 0" xyz="1.319550947539279 0 0" />
     <axis xyz="0 1 1"/>
       <limit effort="0.0" lower="-3.14159" upper="3.14159" velocity="0.0"/>
    </joint>
    <link name="FrontLeg">
        <inertial>
            <origin xyz="0 0.42020197873437015 0" rpy="0 0 0"/>
            <mass value="1" />
            <inertia ixx="100" ixy="0" ixz="0" iyy="100" iyz="0" izz="100" />
        </inertial>
        <visual>
            <origin xyz="0 0.42020197873437015 0" rpy="0 0 0"/>
            <geometry>
                <box size="0.2 0.8404039574687403 0.2" />
            </geometry>
            <material name="Cyan">
                <color rgba="0 1.0 1.0 1.0"/>
            </material>
        </visual>
        <collision>
            <origin xyz="0 0.42020197873437015 0" rpy="0 0 0"/>
            <geometry>
                <box size="0.2 0.8404039574687403 0.2" />
            </geometry>
        </collision>
    </link>
    <link name="BackLeg">
        <inertial>
            <origin xyz="0 -0.4149980291050893 0" rpy="0 0 0"/>
            <mass value="1" />
            <inertia ixx="100" ixy="0" ixz="0" iyy="100" iyz="0" izz="100" />
        </inertial>
        <visual>
            <origin xyz="0 -0.4149980291050893 0" rpy="0 0 0"/>
            <geometry>
                <box size="0.2 0.8299960582101786 0.2" />
            </geometry>
            <material name="Cyan">
                <color rgba="0 1.0 1.0 1.0"/>
            </material>
        </visual>
        <collision>
            <origin xyz="0 -0.4149980291050893 0" rpy="0 0 0"/>
            <geometry>
                <box size="0.2 0.8299960582101786 0.2" />
            </geometry>
        </collision>
    </link>
    <link name="LeftLeg">
        <inertial>
            <origin xyz="-0.6071217113716637 0 0" rpy="0 0 0"/>
            <mass value="1" />
            <inertia ixx="100" ixy="0" ixz="0" iyy="100" iyz="0" izz="100" />
        </inertial>
        <visual>
            <origin xyz="-0.6071217113716637 0 0" rpy="0 0 0"/>
            <geometry>
                <box size="1.2142434227433274 0.2 0.2" />
            </geometry>
            <material name="Cyan">
                <color rgba="0 1.0 1.0 1.0"/>
            </material>
        </visual>
        <collision>
            <origin xyz="-0.6071217113716637 0 0" rpy="0 0 0"/>
            <geometry>
                <box size="1.2142434227433274 0.2 0.2" />
            </geometry>
        </collision>
    </link>
    <link name="RightLeg">
        <inertial>
            <origin xyz="0.6597754737696395 0 0" rpy="0 0 0"/>
            <mass value="1" />
            <inertia ixx="100" ixy="0" ixz="0" iyy="100" iyz="0" izz="100" />
        </inertial>
        <visual>
            <origin xyz="0.6597754737696395 0 0" rpy="0 0 0"/>
            <geometry>
                <box size="1.319550947539279 0.2 0.2" />
            </geometry>
            <material name="Cyan">
                <color rgba="0 1.0 1.0 1.0"/>
            </material>
        </visual>
        <collision>
            <origin xyz="0.6597754737696395 0 0" rpy="0 0 0"/>
            <geometry>
                <box size="1.319550947539279 0.2 0.2" />
            </geometry>
        </collision>
    </link>
    <link name="FrontLowerLeg">
        <inertial>
            <origin xyz="0 0 -0.34556056340917696" rpy="0 0 0"/>
            <mass value="1" />
            <inertia ixx="100" ixy="0" ixz="0" iyy="100" iyz="0" izz="100" />
        </inertial>
        <visual>
            <origin xyz="0 0 -0.34556056340917696" rpy="0 0 0"/>
            <geometry>
                <box size="0.2 0.2 0.6911211268183539" />
            </geometry>
            <material name="Cyan">
                <color rgba="0 1.0 1.0 1.0"/>
            </material>
        </visual>
        <collision>
            <origin xyz="0 0 -0.34556056340917696" rpy="0 0 0"/>
            <geometry>
                <box size="0.2 0.2 0.6911211268183539" />
            </geometry>
        </collision>
    </link>
    <link name="BackLowerLeg">
        <inertial>
            <origin xyz="0 0 -0.6556161607567182" rpy="0 0 0"/>
            <mass value="1" />
            <inertia ixx="100" ixy="0" ixz="0" iyy="100" iyz="0" izz="100" />
        </inertial>
        <visual>
            <origin xyz="0 0 -0.6556161607567182" rpy="0 0 0"/>
            <geometry>
                <box size="0.2 0.2 1.3112323215134365" />
            </geometry>
            <material name="Cyan">
                <color rgba="0 1.0 1.0 1.0"/>
            </material>
        </visual>
        <collision>
            <origin xyz="0 0 -0.6556161607567182" rpy="0 0 0"/>
            <geometry>
                <box size="0.2 0.2 1.3112323215134365" />
            </geometry>
        </collision>
    </link>
    <link name="LeftLowerLeg">
        <inertial>
            <origin xyz="0 0 -0.3222563368547099" rpy="0 0 0"/>
            <mass value="1" />
            <inertia ixx="100" ixy="0" ixz="0" iyy="100" iyz="0" izz="100" />
        </inertial>
        <visual>
            <origin xyz="0 0 -0.3222563368547099" rpy="0 0 0"/>
            <geometry>
                <box size="0.2 0.2 0.6445126737094198" />
            </geometry>
            <material name="Cyan">
                <color rgba="0 1.0 1.0 1.0"/>
            </material>
        </visual>
        <collision>
            <origin xyz="0 0 -0.3222563368547099" rpy="0 0 0"/>
            <geometry>
                <box size="0.2 0.2 0.6445126737094198" />
            </geometry>
        </collision>
    </link>
    <link name="RightLowerLeg">
        <inertial>
            <origin xyz="0 0 -0.27471902758852884" rpy="0 0 0"/>
            <mass value="1" />
            <inertia ixx="100" ixy="0" ixz="0" iyy="100" iyz="0" izz="100" />
        </inertial>
        <visual>
            <origin xyz="0 0 -0.27471902758852884" rpy="0 0 0"/>
            <geometry>
                <box size="0.2 0.2 0.5494380551770577" />
            </geometry>
            <material name="Cyan">
                <color rgba="0 1.0 1.0 1.0"/>
            </material>
        </visual>
        <collision>
            <origin xyz="0 0 -0.27471902758852884" rpy="0 0 0"/>
            <geometry>
                <box size="0.2 0.2 0.5494380551770577" />
            </geometry>
        </collision>
    </link>
</robot>